'\'Traceback (most recent call last):\\n  File "C:\\\\Users\\\\14917\\\\Desktop\\\\study\\\\PythonFramework0To1\\\\从0到1搭建自动化测试框架-原理-实现与工程实践\\\\Chapter13\\\\main.py", line 93, in func_run\\n    getattr(cls_instance, func.__name__).__wrapped__(cls_instance)\\n  File "C:\\\\Users\\\\14917\\\\Desktop\\\\study\\\\PythonFramework0To1\\\\从0到1搭建自动化测试框架-原理-实现与工程实践\\\\Chapter13\\\\tests\\\\test_2.py", line 26, in test_unknown_error\\n    raise ValueError("User Error")\\nValueError: User Error\\n\''